2025-03-26 01:22:15,801 - INFO - Starting keyword analysis process
2025-03-26 01:22:15,801 - INFO - Output will be saved to: output/keyword_analysis.xlsx
2025-03-26 01:22:15,801 - INFO - Loading input file: output/cleaned_data.xlsx
2025-03-26 01:22:15,801 - ERROR - Error in keyword analysis: Input file not found: output/cleaned_data.xlsx
Traceback (most recent call last):
  File "C:\Users\gaalm\Desktop\TDK\TDK\modules\keyword_analyzer.py", line 50, in analyze_keywords
    wb = openpyxl.load_workbook(input_file)
         ^^^^^^^^^^^^^^^^^^^^^^^^^^^^^^^^^^
  File "C:\Users\gaalm\AppData\Local\Programs\Python\Python312\Lib\site-packages\openpyxl\reader\excel.py", line 344, in load_workbook
    reader = ExcelReader(filename, read_only, keep_vba,
             ^^^^^^^^^^^^^^^^^^^^^^^^^^^^^^^^^^^^^^^^^^
  File "C:\Users\gaalm\AppData\Local\Programs\Python\Python312\Lib\site-packages\openpyxl\reader\excel.py", line 123, in __init__
    self.archive = _validate_archive(fn)
                   ^^^^^^^^^^^^^^^^^^^^^
  File "C:\Users\gaalm\AppData\Local\Programs\Python\Python312\Lib\site-packages\openpyxl\reader\excel.py", line 95, in _validate_archive
    archive = ZipFile(filename, 'r')
              ^^^^^^^^^^^^^^^^^^^^^^
  File "C:\Users\gaalm\AppData\Local\Programs\Python\Python312\Lib\zipfile\__init__.py", line 1331, in __init__
    self.fp = io.open(file, filemode)
              ^^^^^^^^^^^^^^^^^^^^^^^
FileNotFoundError: [Errno 2] No such file or directory: 'output/cleaned_data.xlsx'

During handling of the above exception, another exception occurred:

Traceback (most recent call last):
  File "C:\Users\gaalm\Desktop\TDK\TDK\modules\keyword_analyzer.py", line 53, in analyze_keywords
    raise Exception(f"Input file not found: {input_file}")
Exception: Input file not found: output/cleaned_data.xlsx
2025-03-26 01:24:53,706 - INFO - Starting keyword analysis process
2025-03-26 01:24:53,706 - INFO - Output will be saved to: output/keyword_analysis.xlsx
2025-03-26 01:24:53,707 - INFO - Loading input file: output/cleaned_data.xlsx
2025-03-26 01:24:53,707 - ERROR - Error in keyword analysis: Error loading workbook: File is not a zip file
Traceback (most recent call last):
  File "C:\Users\gaalm\Desktop\TDK\TDK\modules\keyword_analyzer.py", line 50, in analyze_keywords
    wb = openpyxl.load_workbook(input_file)
         ^^^^^^^^^^^^^^^^^^^^^^^^^^^^^^^^^^
  File "C:\Users\gaalm\AppData\Local\Programs\Python\Python312\Lib\site-packages\openpyxl\reader\excel.py", line 344, in load_workbook
    reader = ExcelReader(filename, read_only, keep_vba,
             ^^^^^^^^^^^^^^^^^^^^^^^^^^^^^^^^^^^^^^^^^^
  File "C:\Users\gaalm\AppData\Local\Programs\Python\Python312\Lib\site-packages\openpyxl\reader\excel.py", line 123, in __init__
    self.archive = _validate_archive(fn)
                   ^^^^^^^^^^^^^^^^^^^^^
  File "C:\Users\gaalm\AppData\Local\Programs\Python\Python312\Lib\site-packages\openpyxl\reader\excel.py", line 95, in _validate_archive
    archive = ZipFile(filename, 'r')
              ^^^^^^^^^^^^^^^^^^^^^^
  File "C:\Users\gaalm\AppData\Local\Programs\Python\Python312\Lib\zipfile\__init__.py", line 1349, in __init__
    self._RealGetContents()
  File "C:\Users\gaalm\AppData\Local\Programs\Python\Python312\Lib\zipfile\__init__.py", line 1416, in _RealGetContents
    raise BadZipFile("File is not a zip file")
zipfile.BadZipFile: File is not a zip file

During handling of the above exception, another exception occurred:

Traceback (most recent call last):
  File "C:\Users\gaalm\Desktop\TDK\TDK\modules\keyword_analyzer.py", line 55, in analyze_keywords
    raise Exception(f"Error loading workbook: {str(e)}")
Exception: Error loading workbook: File is not a zip file
2025-03-26 01:30:46,064 - INFO - Starting keyword analysis process
2025-03-26 01:30:46,065 - INFO - Output will be saved to: output/keyword_analysis.xlsx
2025-03-26 01:30:46,065 - INFO - Loading input file: output/cleaned_data.xlsx
2025-03-26 01:30:46,065 - ERROR - Error in keyword analysis: Error loading workbook: File is not a zip file
Traceback (most recent call last):
  File "C:\Users\gaalm\Desktop\TDK\TDK\modules\keyword_analyzer.py", line 50, in analyze_keywords
    wb = openpyxl.load_workbook(input_file)
         ^^^^^^^^^^^^^^^^^^^^^^^^^^^^^^^^^^
  File "C:\Users\gaalm\AppData\Local\Programs\Python\Python312\Lib\site-packages\openpyxl\reader\excel.py", line 344, in load_workbook
    reader = ExcelReader(filename, read_only, keep_vba,
             ^^^^^^^^^^^^^^^^^^^^^^^^^^^^^^^^^^^^^^^^^^
  File "C:\Users\gaalm\AppData\Local\Programs\Python\Python312\Lib\site-packages\openpyxl\reader\excel.py", line 123, in __init__
    self.archive = _validate_archive(fn)
                   ^^^^^^^^^^^^^^^^^^^^^
  File "C:\Users\gaalm\AppData\Local\Programs\Python\Python312\Lib\site-packages\openpyxl\reader\excel.py", line 95, in _validate_archive
    archive = ZipFile(filename, 'r')
              ^^^^^^^^^^^^^^^^^^^^^^
  File "C:\Users\gaalm\AppData\Local\Programs\Python\Python312\Lib\zipfile\__init__.py", line 1349, in __init__
    self._RealGetContents()
  File "C:\Users\gaalm\AppData\Local\Programs\Python\Python312\Lib\zipfile\__init__.py", line 1416, in _RealGetContents
    raise BadZipFile("File is not a zip file")
zipfile.BadZipFile: File is not a zip file

During handling of the above exception, another exception occurred:

Traceback (most recent call last):
  File "C:\Users\gaalm\Desktop\TDK\TDK\modules\keyword_analyzer.py", line 55, in analyze_keywords
    raise Exception(f"Error loading workbook: {str(e)}")
Exception: Error loading workbook: File is not a zip file
2025-03-26 01:47:13,445 - INFO - Starting keyword analysis process
2025-03-26 01:47:13,445 - INFO - Output will be saved to: output/keyword_analysis.xlsx
2025-03-26 01:47:13,446 - INFO - Loading input file: output/cleaned_data.xlsx
2025-03-26 01:47:13,446 - ERROR - Error in keyword analysis: Error loading workbook: File is not a zip file
Traceback (most recent call last):
  File "C:\Users\gaalm\Desktop\TDK\TDK\modules\keyword_analyzer.py", line 50, in analyze_keywords
    wb = openpyxl.load_workbook(input_file)
         ^^^^^^^^^^^^^^^^^^^^^^^^^^^^^^^^^^
  File "C:\Users\gaalm\AppData\Local\Programs\Python\Python312\Lib\site-packages\openpyxl\reader\excel.py", line 344, in load_workbook
    reader = ExcelReader(filename, read_only, keep_vba,
             ^^^^^^^^^^^^^^^^^^^^^^^^^^^^^^^^^^^^^^^^^^
  File "C:\Users\gaalm\AppData\Local\Programs\Python\Python312\Lib\site-packages\openpyxl\reader\excel.py", line 123, in __init__
    self.archive = _validate_archive(fn)
                   ^^^^^^^^^^^^^^^^^^^^^
  File "C:\Users\gaalm\AppData\Local\Programs\Python\Python312\Lib\site-packages\openpyxl\reader\excel.py", line 95, in _validate_archive
    archive = ZipFile(filename, 'r')
              ^^^^^^^^^^^^^^^^^^^^^^
  File "C:\Users\gaalm\AppData\Local\Programs\Python\Python312\Lib\zipfile\__init__.py", line 1349, in __init__
    self._RealGetContents()
  File "C:\Users\gaalm\AppData\Local\Programs\Python\Python312\Lib\zipfile\__init__.py", line 1416, in _RealGetContents
    raise BadZipFile("File is not a zip file")
zipfile.BadZipFile: File is not a zip file

During handling of the above exception, another exception occurred:

Traceback (most recent call last):
  File "C:\Users\gaalm\Desktop\TDK\TDK\modules\keyword_analyzer.py", line 55, in analyze_keywords
    raise Exception(f"Error loading workbook: {str(e)}")
Exception: Error loading workbook: File is not a zip file
2025-03-26 01:48:14,605 - INFO - Starting keyword analysis process
2025-03-26 01:48:14,606 - INFO - Output will be saved to: output/keyword_analysis.xlsx
2025-03-26 01:48:14,606 - INFO - Loading input file: output/cleaned_data.xlsx
2025-03-26 01:48:14,606 - ERROR - Error in keyword analysis: Input file not found: output/cleaned_data.xlsx
Traceback (most recent call last):
  File "C:\Users\gaalm\Desktop\TDK\TDK\modules\keyword_analyzer.py", line 50, in analyze_keywords
    wb = openpyxl.load_workbook(input_file)
         ^^^^^^^^^^^^^^^^^^^^^^^^^^^^^^^^^^
  File "C:\Users\gaalm\AppData\Local\Programs\Python\Python312\Lib\site-packages\openpyxl\reader\excel.py", line 344, in load_workbook
    reader = ExcelReader(filename, read_only, keep_vba,
             ^^^^^^^^^^^^^^^^^^^^^^^^^^^^^^^^^^^^^^^^^^
  File "C:\Users\gaalm\AppData\Local\Programs\Python\Python312\Lib\site-packages\openpyxl\reader\excel.py", line 123, in __init__
    self.archive = _validate_archive(fn)
                   ^^^^^^^^^^^^^^^^^^^^^
  File "C:\Users\gaalm\AppData\Local\Programs\Python\Python312\Lib\site-packages\openpyxl\reader\excel.py", line 95, in _validate_archive
    archive = ZipFile(filename, 'r')
              ^^^^^^^^^^^^^^^^^^^^^^
  File "C:\Users\gaalm\AppData\Local\Programs\Python\Python312\Lib\zipfile\__init__.py", line 1331, in __init__
    self.fp = io.open(file, filemode)
              ^^^^^^^^^^^^^^^^^^^^^^^
FileNotFoundError: [Errno 2] No such file or directory: 'output/cleaned_data.xlsx'

During handling of the above exception, another exception occurred:

Traceback (most recent call last):
  File "C:\Users\gaalm\Desktop\TDK\TDK\modules\keyword_analyzer.py", line 53, in analyze_keywords
    raise Exception(f"Input file not found: {input_file}")
Exception: Input file not found: output/cleaned_data.xlsx
2025-03-26 01:51:20,560 - INFO - Starting keyword analysis process
2025-03-26 01:51:20,561 - INFO - Output will be saved to: output/keyword_analysis.xlsx
2025-03-26 01:51:20,561 - INFO - Loading input file: output/cleaned_data.xlsx
2025-03-26 01:51:20,562 - ERROR - Error in keyword analysis: Input file not found: output/cleaned_data.xlsx
Traceback (most recent call last):
  File "C:\Users\gaalm\Desktop\TDK\TDK\modules\keyword_analyzer.py", line 50, in analyze_keywords
    wb = openpyxl.load_workbook(input_file)
         ^^^^^^^^^^^^^^^^^^^^^^^^^^^^^^^^^^
  File "C:\Users\gaalm\AppData\Local\Programs\Python\Python312\Lib\site-packages\openpyxl\reader\excel.py", line 344, in load_workbook
    reader = ExcelReader(filename, read_only, keep_vba,
             ^^^^^^^^^^^^^^^^^^^^^^^^^^^^^^^^^^^^^^^^^^
  File "C:\Users\gaalm\AppData\Local\Programs\Python\Python312\Lib\site-packages\openpyxl\reader\excel.py", line 123, in __init__
    self.archive = _validate_archive(fn)
                   ^^^^^^^^^^^^^^^^^^^^^
  File "C:\Users\gaalm\AppData\Local\Programs\Python\Python312\Lib\site-packages\openpyxl\reader\excel.py", line 95, in _validate_archive
    archive = ZipFile(filename, 'r')
              ^^^^^^^^^^^^^^^^^^^^^^
  File "C:\Users\gaalm\AppData\Local\Programs\Python\Python312\Lib\zipfile\__init__.py", line 1331, in __init__
    self.fp = io.open(file, filemode)
              ^^^^^^^^^^^^^^^^^^^^^^^
FileNotFoundError: [Errno 2] No such file or directory: 'output/cleaned_data.xlsx'

During handling of the above exception, another exception occurred:

Traceback (most recent call last):
  File "C:\Users\gaalm\Desktop\TDK\TDK\modules\keyword_analyzer.py", line 53, in analyze_keywords
    raise Exception(f"Input file not found: {input_file}")
Exception: Input file not found: output/cleaned_data.xlsx
2025-03-26 01:53:53,196 - INFO - Starting keyword analysis process
2025-03-26 01:53:53,196 - INFO - Output will be saved to: output/keyword_analysis.xlsx
2025-03-26 01:53:53,196 - INFO - Loading input file: output/cleaned_data.xlsx
2025-03-26 01:53:53,196 - ERROR - Error in keyword analysis: Input file not found: output/cleaned_data.xlsx
Traceback (most recent call last):
  File "C:\Users\gaalm\Desktop\TDK\TDK\modules\keyword_analyzer.py", line 50, in analyze_keywords
    wb = openpyxl.load_workbook(input_file)
         ^^^^^^^^^^^^^^^^^^^^^^^^^^^^^^^^^^
  File "C:\Users\gaalm\AppData\Local\Programs\Python\Python312\Lib\site-packages\openpyxl\reader\excel.py", line 344, in load_workbook
    reader = ExcelReader(filename, read_only, keep_vba,
             ^^^^^^^^^^^^^^^^^^^^^^^^^^^^^^^^^^^^^^^^^^
  File "C:\Users\gaalm\AppData\Local\Programs\Python\Python312\Lib\site-packages\openpyxl\reader\excel.py", line 123, in __init__
    self.archive = _validate_archive(fn)
                   ^^^^^^^^^^^^^^^^^^^^^
  File "C:\Users\gaalm\AppData\Local\Programs\Python\Python312\Lib\site-packages\openpyxl\reader\excel.py", line 95, in _validate_archive
    archive = ZipFile(filename, 'r')
              ^^^^^^^^^^^^^^^^^^^^^^
  File "C:\Users\gaalm\AppData\Local\Programs\Python\Python312\Lib\zipfile\__init__.py", line 1331, in __init__
    self.fp = io.open(file, filemode)
              ^^^^^^^^^^^^^^^^^^^^^^^
FileNotFoundError: [Errno 2] No such file or directory: 'output/cleaned_data.xlsx'

During handling of the above exception, another exception occurred:

Traceback (most recent call last):
  File "C:\Users\gaalm\Desktop\TDK\TDK\modules\keyword_analyzer.py", line 53, in analyze_keywords
    raise Exception(f"Input file not found: {input_file}")
Exception: Input file not found: output/cleaned_data.xlsx
2025-03-26 01:54:47,877 - INFO - Starting keyword analysis process
2025-03-26 01:54:47,878 - INFO - Output will be saved to: output/keyword_analysis.xlsx
2025-03-26 01:54:47,878 - INFO - Loading input file: output/cleaned_data.xlsx
2025-03-26 01:54:47,878 - ERROR - Error in keyword analysis: Error loading workbook: File is not a zip file
Traceback (most recent call last):
  File "C:\Users\gaalm\Desktop\TDK\TDK\modules\keyword_analyzer.py", line 50, in analyze_keywords
    wb = openpyxl.load_workbook(input_file)
         ^^^^^^^^^^^^^^^^^^^^^^^^^^^^^^^^^^
  File "C:\Users\gaalm\AppData\Local\Programs\Python\Python312\Lib\site-packages\openpyxl\reader\excel.py", line 344, in load_workbook
    reader = ExcelReader(filename, read_only, keep_vba,
             ^^^^^^^^^^^^^^^^^^^^^^^^^^^^^^^^^^^^^^^^^^
  File "C:\Users\gaalm\AppData\Local\Programs\Python\Python312\Lib\site-packages\openpyxl\reader\excel.py", line 123, in __init__
    self.archive = _validate_archive(fn)
                   ^^^^^^^^^^^^^^^^^^^^^
  File "C:\Users\gaalm\AppData\Local\Programs\Python\Python312\Lib\site-packages\openpyxl\reader\excel.py", line 95, in _validate_archive
    archive = ZipFile(filename, 'r')
              ^^^^^^^^^^^^^^^^^^^^^^
  File "C:\Users\gaalm\AppData\Local\Programs\Python\Python312\Lib\zipfile\__init__.py", line 1349, in __init__
    self._RealGetContents()
  File "C:\Users\gaalm\AppData\Local\Programs\Python\Python312\Lib\zipfile\__init__.py", line 1416, in _RealGetContents
    raise BadZipFile("File is not a zip file")
zipfile.BadZipFile: File is not a zip file

During handling of the above exception, another exception occurred:

Traceback (most recent call last):
  File "C:\Users\gaalm\Desktop\TDK\TDK\modules\keyword_analyzer.py", line 55, in analyze_keywords
    raise Exception(f"Error loading workbook: {str(e)}")
Exception: Error loading workbook: File is not a zip file
2025-03-26 01:59:05,458 - INFO - Starting keyword analysis process
2025-03-26 01:59:05,458 - INFO - Output will be saved to: output/keyword_analysis.xlsx
2025-03-26 01:59:05,458 - INFO - Loading input file: output/cleaned_data.xlsx
2025-03-26 01:59:05,458 - ERROR - Error in keyword analysis: Error loading workbook: File is not a zip file
Traceback (most recent call last):
  File "C:\Users\gaalm\Desktop\TDK\TDK\modules\keyword_analyzer.py", line 50, in analyze_keywords
    wb = openpyxl.load_workbook(input_file)
         ^^^^^^^^^^^^^^^^^^^^^^^^^^^^^^^^^^
  File "C:\Users\gaalm\AppData\Local\Programs\Python\Python312\Lib\site-packages\openpyxl\reader\excel.py", line 344, in load_workbook
    reader = ExcelReader(filename, read_only, keep_vba,
             ^^^^^^^^^^^^^^^^^^^^^^^^^^^^^^^^^^^^^^^^^^
  File "C:\Users\gaalm\AppData\Local\Programs\Python\Python312\Lib\site-packages\openpyxl\reader\excel.py", line 123, in __init__
    self.archive = _validate_archive(fn)
                   ^^^^^^^^^^^^^^^^^^^^^
  File "C:\Users\gaalm\AppData\Local\Programs\Python\Python312\Lib\site-packages\openpyxl\reader\excel.py", line 95, in _validate_archive
    archive = ZipFile(filename, 'r')
              ^^^^^^^^^^^^^^^^^^^^^^
  File "C:\Users\gaalm\AppData\Local\Programs\Python\Python312\Lib\zipfile\__init__.py", line 1349, in __init__
    self._RealGetContents()
  File "C:\Users\gaalm\AppData\Local\Programs\Python\Python312\Lib\zipfile\__init__.py", line 1416, in _RealGetContents
    raise BadZipFile("File is not a zip file")
zipfile.BadZipFile: File is not a zip file

During handling of the above exception, another exception occurred:

Traceback (most recent call last):
  File "C:\Users\gaalm\Desktop\TDK\TDK\modules\keyword_analyzer.py", line 55, in analyze_keywords
    raise Exception(f"Error loading workbook: {str(e)}")
Exception: Error loading workbook: File is not a zip file
